Workbook

Sheet (SFD 4-5 Bed) Break Even
A1: 2023 Municipal and School Fiscal Impact Break Even Analysis for Single Family Detached (4-5 Bedroom) in Selected NJ Communities
A3: Single Family Detached (4-5 Bedroom) with Revised Updated 2021 Multipliers
A4: Category | B4: Multiplier
A5: Household Size | B5: 3.369
A6: School Age Children | B6: 0.683
A8: Location | C8: 4-5 Bedroom Single Family Detached "Break Even Analysis" | G8: Fiscal Analysis | K8: Municipal and School Public Finanace Data
A9: County | B9: Municipality | C9: Municipal Tax Supported Cost | D9: School Tax Supported Cost | E9: Total Tax Supported Cost | F9: Market Value "Break Even" | G9: Imputed Average (2023) Market Value of Potential Buyout Properties | H9: Fiscal Surplus or Deficit (Based on Average Buyout Market Value) | I9: Average 2023 Residential Value in Buyout Community | J9: Fiscal Surplus or Deficit (Based on Average Residential Value) | K9: Total Municipal + School Equalized Property Tax Rate | L9: Percent of Total Parcels that are Residential | M9: Percent of Total Assessed Value that is Residential | N9: Average of Residential Parcels % and Assessed Value % | O9: Total Municipal Property Tax Levy | P9: Estimated Residential Share of Total Municipal Property Tax Levy | Q9: 2020 Municipal Population | R9: 2020 Municipal Property Tax Supported Cost Per Person | S9: Total School Property Tax Levy | T9: 2020 Total School Enrollment | U9: 2020 School Property Tax Supported Cost Per Pupil
A10: Camden | B10: Bellmawr | C10: =$B$5*R10 -> 2442.4749 | D10: =U10*$B$6 -> 0 | E10: =C10+D10 -> 2442.4749 | F10: =E10/(K10/100) -> 103626.43 | G10: 129554 | H10: =G10-F10 -> 25927.572 | I10: 187760 | J10: =I10-F10 -> 84133.572 | K10: 2.357 | L10: 0.9525 | M10: 0.7751 | N10: =(L10+M10)/2 -> 0.8638 | O10: 9805512 | P10: =N10*O10 -> 8470001.3 | Q10: 11683 | R10: =P10/Q10 -> 724.98513
A11: Camden | B11: Brooklawn | C11: =$B$5*R11 -> 3357.7384 | D11: =U11*$B$6 -> 4036.53 | E11: =C11+D11 -> 7394.2684 | F11: =E11/(K11/100) -> 307966.2 | G11: 94881 | H11: =G11-F11 -> -213085.2 | I11: 137509 | J11: =I11-F11 -> -170457.2 | K11: 2.401 | L11: 0.9117 | M11: 0.6552 | N11: =(L11+M11)/2 -> 0.78345 | O11: 2297483 | P11: =N11*O11 -> 1799963.1 | Q11: 1806 | R11: =P11/Q11 -> 996.65728 | S11: 1554520 | T11: 263 | U11: 5910
A12: Camden | B12: Gloucester City | C12: =$B$5*R12 -> 3702.4248 | D12: =U12*$B$6 -> 1921.962 | E12: =C12+D12 -> 5624.3868 | F12: =E12/(K12/100) -> 190141.54 | G12: 94239 | H12: =G12-F12 -> -95902.541 | I12: 136578 | J12: =I12-F12 -> -53563.541 | K12: 2.958 | L12: 0.9331 | M12: 0.7821 | N12: =(L12+M12)/2 -> 0.8576 | O12: 14690502 | P12: =N12*O12 -> 12598575 | Q12: 11464 | R12: =P12/Q12 -> 1098.9685 | S12: 26724337 | T12: 2390 | U12: 2814
A13: Camden | B13: Mt Ephraim | C13: =$B$5*R13 -> 3062.6257 | D13: =U13*$B$6 -> 11261.987 | E13: =C13+D13 -> 14324.613 | F13: =E13/(K13/100) -> 498941.58 | G13: 133784 | H13: =G13-F13 -> -365157.58 | I13: 193890 | J13: =I13-F13 -> -305051.58 | K13: 2.871 | L13: 0.946 | M13: 0.8759 | N13: =(L13+M13)/2 -> 0.91095 | O13: 4629379 | P13: =N13*O13 -> 4217132.8 | Q13: 4639 | R13: =P13/Q13 -> 909.06075 | S13: 7090693 | T13: 430 | U13: 16489
A14: Gloucester | B14: Westville | C14: =$B$5*R14 -> 2181.3657 | D14: =U14*$B$6 -> 0 | E14: =C14+D14 -> 2181.3657 | F14: =E14/(K14/100) -> 76085.306 | G14: 113598 | H14: =G14-F14 -> 37512.694 | I14: 164635 | J14: =I14-F14 -> 88549.694 | K14: 2.867 | L14: 0.8626 | M14: 0.807 | N14: =(L14+M14)/2 -> 0.8348 | O14: 3338238 | P14: =N14*O14 -> 2786761.1 | Q14: 4304 | R14: =P14/Q14 -> 647.48166

Sheet (SFD 4-5 Bed) Muni Break Even
A1: 2023 Municipal Fiscal Impact Break Even Analysis for Single Family Detached (4-5 Bedroom) in Selected NJ Communities
A3: Single Family Detached (4-5 Bedroom) with Revised Updated 2021 Multipliers
A4: Category | B4: Multiplier
A5: Household Size | B5: 3.369
A6: School Age Children | B6: 0.683
A8: Location | C8: 4-5 Bedroom Single Family Detached Municipal"Break Even Analysis" | E8: Fiscal Analysis | I8: Municipal Public Finance Data
A9: County | B9: Municipality | C9: Municipal Tax Supported Cost | D9: Market Value "Break Even" | E9: Imputed Average (2023) Market Value of Potential Buyout Properties | F9: Fiscal Surplus or Deficit (Based on Average Buyout Market Value) | G9: Average 2023 Residential Value in Buyout Community | H9: Fiscal Surplus or Deficit (Based on Average Residential Value) | I9: Municipal Equalized Property Tax Rate | J9: Percent of Total Parcels that are Residential | K9: Percent of Total Assessed Value that is Residential | L9: Average of Residential Parcels % and Assessed Value % | M9: Total Municipal Property Tax Levy | N9: Estimated Residential Share of Total Municipal Property Tax Levy | O9: 2022 Municipal Population | P9: 2023 Municipal Property Tax Supported Cost Per Person
A10: Camden | B10: Bellmawr | C10: =$B$5*P10 -> 2442.4749 | D10: =C10/(I10/100) -> 253106.21 | E10: 129554 | F10: =E10-D10 -> -123552.21 | G10: 187760 | H10: =G10-D10 -> -65346.207 | I10: 0.965 | J10: 0.9525 | K10: 0.7751 | L10: =(J10+K10)/2 -> 0.8638 | M10: 9805512 | N10: =L10*M10 -> 8470001.3 | O10: 11683 | P10: =N10/O10 -> 724.98513
A11: Camden | B11: Brooklawn | C11: =$B$5*P11 -> 3357.7384 | D11: =C11/(I11/100) -> 234478.94 | E11: 94881 | F11: =E11-D11 -> -139597.94 | G11: 137509 | H11: =G11-D11 -> -96969.938 | I11: 1.432 | J11: 0.9117 | K11: 0.6552 | L11: =(J11+K11)/2 -> 0.78345 | M11: 2297483 | N11: =L11*M11 -> 1799963.1 | O11: 1806 | P11: =N11/O11 -> 996.65728
A12: Camden | B12: Gloucester City | C12: =$B$5*P12 -> 3702.4248 | D12: =C12/(I12/100) -> 179816.65 | E12: 94239 | F12: =E12-D12 -> -85577.647 | G12: 136578 | H12: =G12-D12 -> -43238.647 | I12: 2.059 | J12: 0.9331 | K12: 0.7821 | L12: =(J12+K12)/2 -> 0.8576 | M12: 14690502 | N12: =L12*M12 -> 12598575 | O12: 11464 | P12: =N12/O12 -> 1098.9685
A13: Camden | B13: Mt Ephraim | C13: =$B$5*P13 -> 3062.6257 | D13: =C13/(I13/100) -> 270072.81 | E13: 133784 | F13: =E13-D13 -> -136288.81 | G13: 193890 | H13: =G13-D13 -> -76182.809 | I13: 1.134 | J13: 0.946 | K13: 0.8759 | L13: =(J13+K13)/2 -> 0.91095 | M13: 4629379 | N13: =L13*M13 -> 4217132.8 | O13: 4639 | P13: =N13/O13 -> 909.06075
A14: Gloucester | B14: Westville | C14: =$B$5*P14 -> 2181.3657 | D14: =C14/(I14/100) -> 219895.74 | E14: 113598 | F14: =E14-D14 -> -106297.74 | G14: 164635 | H14: =G14-D14 -> -55260.739 | I14: 0.992 | J14: 0.8626 | K14: 0.807 | L14: =(J14+K14)/2 -> 0.8348 | M14: 3338238 | N14: =L14*M14 -> 2786761.1 | O14: 4304 | P14: =N14/O14 -> 647.48166

Sheet (SFD 3 Bed) Break Even
A1: 2020 Break Even Analysis for Single Family Detached (3 Bedroom) in Selected NJ Communities
A3: Single Family Detached (3 Bedroom) Multipliers
A4: Category | B4: Multiplier
A5: Household Size | B5: 2.757
A6: School Age Children | B6: 0.425
A8: Location | C8: 3 Bedroom Single Family Detached "Break Even Analysis" | G8: Fiscal Analysis | K8: School and Municipal Fiscal Impact Analysis
A9: County | B9: Municipality | C9: Municipal Tax Supported Cost | D9: School Tax Supported Cost | E9: Total Tax Supported Cost | F9: Market Value "Break Even" | G9: Average Real (2020) Market Value of Buyout Properties | H9: Fiscal Surplus or Deficit (Based on Average Buyout Market Value) | I9: Average 2020 Residential Value in Buyout Community | J9: Fiscal Surplus or Deficit (Based on Average Residential Value) | K9: Total Municipal + School Equalized Property Tax Rate | L9: Percent of Total Parcels that are Residential | M9: Percent of Total Assessed Value that is Residential | N9: Average of Residential Parcels % and Assessed Value % | O9: Total Municipal Property Tax Levy | P9: Estimated Residential Share of Total Municipal Property Tax Levy | Q9: 2020 Municipal Population | R9: 2020 Municipal Property Tax Supported Cost Per Person | S9: Total School Property Tax Levy | T9: 2020 Total School Enrollment | U9: 2020 School Property Tax Supported Cost Per Pupil
A10: Atlantic | B10: Pleasantville City | C10: =$B$5*R10 -> 2629.6625 | D10: =U10*$B$6 -> 988.24162 | E10: =C10+D10 -> 3617.9042 | F10: =E10/(K10/100) -> 82783.394 | G10: 60235 | H10: =G10-F10 -> -22548.394 | I10: 98362.768 | J10: =I10-F10 -> 15579.374 | K10: ='Tax Levies and EQ Tax Rates'!O5 -> 4.370326 | L10: ='# and Assessed Value of Parcels'!G5/'# and Assessed Value of Parcels'!O5 -> 0.92172813 | M10: ='# and Assessed Value of Parcels'!H5/'# and Assessed Value of Parcels'!P5 -> 0.73101366 | N10: =(L10+M10)/2 -> 0.8263709 | O10: ='Tax Levies and EQ Tax Rates'!I5 -> 23810385 | P10: =N10*O10 -> 19676209 | Q10: 20629 | R10: =P10/Q10 -> 953.81304 | S10: ='Tax Levies and EQ Tax Rates'!C5 -> 10152148 | T10: 4366 | U10: =S10/T10 -> 2325.2744
A11: Bergen | B11: New Milford Borough | C11: =$B$5*R11 -> 2706.2841 | D11: =U11*$B$6 -> 6563.9319 | E11: =C11+D11 -> 9270.216 | F11: =E11/(K11/100) -> 365033.9 | G11: 373724 | H11: =G11-F11 -> 8690.095 | I11: 426888.09 | J11: =I11-F11 -> 61854.185 | K11: ='Tax Levies and EQ Tax Rates'!O7 -> 2.5395493 | L11: ='# and Assessed Value of Parcels'!G7/'# and Assessed Value of Parcels'!O7 -> 0.98144233 | M11: ='# and Assessed Value of Parcels'!H7/'# and Assessed Value of Parcels'!P7 -> 0.94433259 | N11: =(L11+M11)/2 -> 0.96288746 | O11: ='Tax Levies and EQ Tax Rates'!I7 -> 17251960 | P11: =N11*O11 -> 16611696 | Q11: 16923 | R11: =P11/Q11 -> 981.6047 | S11: ='Tax Levies and EQ Tax Rates'!C7 -> 35244453 | T11: 2282 | U11: =S11/T11 -> 15444.546
A12: Essex | B12: Newark City | C12: =$B$5*R12 -> 1545.9463 | D12: =U12*$B$6 -> 959.89573 | E12: =C12+D12 -> 2505.842 | F12: =E12/(K12/100) -> 94709.031 | G12: 164529.67 | H12: =G12-F12 -> 69820.636 | I12: 206835.02 | J12: =I12-F12 -> 112125.99 | K12: ='Tax Levies and EQ Tax Rates'!O18 -> 2.6458321 | L12: ='# and Assessed Value of Parcels'!G18/'# and Assessed Value of Parcels'!O18 -> 0.84162884 | M12: ='# and Assessed Value of Parcels'!H18/'# and Assessed Value of Parcels'!P18 -> 0.54365223 | N12: =(L12+M12)/2 -> 0.69264054 | O12: ='Tax Levies and EQ Tax Rates'!I18 -> 252218004 | P12: =N12*O12 -> 1.7469641e+08 | Q12: 311549 | R12: =P12/Q12 -> 560.73495 | S12: ='Tax Levies and EQ Tax Rates'!C18 -> 135819599 | T12: 60135 | U12: =S12/T12 -> 2258.5782
A13: Middlesex | B13: East Brunswick Township | C13: =$B$5*R13 -> 2171.3074 | D13: =U13*$B$6 -> 6949.8966 | E13: =C13+D13 -> 9121.204 | F13: =E13/(K13/100) -> 383523.89 | G13: 228185.83 | H13: =G13-F13 -> -155338.06 | I13: 380312.49 | J13: =I13-F13 -> -3211.4023 | K13: ='Tax Levies and EQ Tax Rates'!O20 -> 2.3782623 | L13: ='# and Assessed Value of Parcels'!G20/'# and Assessed Value of Parcels'!O20 -> 0.95667524 | M13: ='# and Assessed Value of Parcels'!H20/'# and Assessed Value of Parcels'!P20 -> 0.81220548 | N13: =(L13+M13)/2 -> 0.88444036 | O13: ='Tax Levies and EQ Tax Rates'!I20 -> 44269380 | P13: =N13*O13 -> 39153626 | Q13: 49715 | R13: =P13/Q13 -> 787.56163 | S13: ='Tax Levies and EQ Tax Rates'!C20 -> 137771480 | T13: 8425 | U13: =S13/T13 -> 16352.698
A14: Middlesex | B14: Old Bridge Township | C14: =$B$5*R14 -> 1449.0294 | D14: =U14*$B$6 -> 5612.7613 | E14: =C14+D14 -> 7061.7907 | F14: =E14/(K14/100) -> 419009.73 | G14: 131130.71 | H14: =G14-F14 -> -287879.02 | I14: 375525.05 | J14: =I14-F14 -> -43484.678 | K14: ='Tax Levies and EQ Tax Rates'!O21 -> 1.6853524 | L14: ='# and Assessed Value of Parcels'!G21/'# and Assessed Value of Parcels'!O21 -> 0.97122792 | M14: ='# and Assessed Value of Parcels'!H21/'# and Assessed Value of Parcels'!P21 -> 0.88589383 | N14: =(L14+M14)/2 -> 0.92856088 | O14: ='Tax Levies and EQ Tax Rates'!I21 -> 37853002 | P14: =N14*O14 -> 35148817 | Q14: 66876 | R14: =P14/Q14 -> 525.58193 | S14: ='Tax Levies and EQ Tax Rates'!C21 -> 106576433 | T14: 8070 | U14: =S14/T14 -> 13206.497
A15: Middlesex | B15: Middlesex Borough | C15: =$B$5*R15 -> 2290.0211 | D15: =U15*$B$6 -> 5510.6844 | E15: =C15+D15 -> 7800.7056 | F15: =E15/(K15/100) -> 330909.58 | G15: 306079.81 | H15: =G15-F15 -> -24829.771 | I15: 324882.84 | J15: =I15-F15 -> -6026.7441 | K15: ='Tax Levies and EQ Tax Rates'!O22 -> 2.3573526 | L15: ='# and Assessed Value of Parcels'!G22/'# and Assessed Value of Parcels'!O22 -> 0.92460317 | M15: ='# and Assessed Value of Parcels'!H22/'# and Assessed Value of Parcels'!P22 -> 0.82398227 | N15: =(L15+M15)/2 -> 0.87429272 | O15: ='Tax Levies and EQ Tax Rates'!I22 -> 13904913 | P15: =N15*O15 -> 12156964 | Q15: 14636 | R15: =P15/Q15 -> 830.62065 | S15: ='Tax Levies and EQ Tax Rates'!C22 -> 26438319 | T15: 2039 | U15: =S15/T15 -> 12966.316
A16: Middlesex | B16: Sayreville Borough | C16: =$B$5*R16 -> 1959.3985 | D16: =U16*$B$6 -> 4365.442 | E16: =C16+D16 -> 6324.8405 | F16: =E16/(K16/100) -> 321163.24 | G16: 208675.08 | H16: =G16-F16 -> -112488.16 | I16: 330954.76 | J16: =I16-F16 -> 9791.5223 | K16: ='Tax Levies and EQ Tax Rates'!O23 -> 1.9693538 | L16: ='# and Assessed Value of Parcels'!G23/'# and Assessed Value of Parcels'!O23 -> 0.96279666 | M16: ='# and Assessed Value of Parcels'!H23/'# and Assessed Value of Parcels'!P23 -> 0.85286918 | N16: =(L16+M16)/2 -> 0.90783292 | O16: ='Tax Levies and EQ Tax Rates'!I23 -> 35498458 | P16: =N16*O16 -> 32226669 | Q16: 45345 | R16: =P16/Q16 -> 710.69949 | S16: ='Tax Levies and EQ Tax Rates'!C23 -> 67957093 | T16: 6616 | U16: =S16/T16 -> 10271.628
A17: Middlesex | B17: South River Borough | C17: =$B$5*R17 -> 1682.9131 | D17: =U17*$B$6 -> 3171.173 | E17: =C17+D17 -> 4854.0861 | F17: =E17/(K17/100) -> 255903.15 | G17: 163469.67 | H17: =G17-F17 -> -92433.485 | I17: 293469.91 | J17: =I17-F17 -> 37566.757 | K17: ='Tax Levies and EQ Tax Rates'!O24 -> 1.896845 | L17: ='# and Assessed Value of Parcels'!G24/'# and Assessed Value of Parcels'!O24 -> 0.95376862 | M17: ='# and Assessed Value of Parcels'!H24/'# and Assessed Value of Parcels'!P24 -> 0.87694473 | N17: =(L17+M17)/2 -> 0.91535668 | O17: ='Tax Levies and EQ Tax Rates'!I24 -> 10748447 | P17: =N17*O17 -> 9838662.7 | Q17: 16118 | R17: =P17/Q17 -> 610.41461 | S17: ='Tax Levies and EQ Tax Rates'!C24 -> 18146571 | T17: 2432 | U17: =S17/T17 -> 7461.5835
A18: Middlesex | B18: Woodbridge Township | C18: =$B$5*R18 -> 2315.5769 | D18: =U18*$B$6 -> 5638.8502 | E18: =C18+D18 -> 7954.4271 | F18: =E18/(K18/100) -> 340011.86 | G18: 232839.67 | H18: =G18-F18 -> -107172.19 | I18: 307619.51 | J18: =I18-F18 -> -32392.358 | K18: ='Tax Levies and EQ Tax Rates'!O25 -> 2.3394558 | L18: ='# and Assessed Value of Parcels'!G25/'# and Assessed Value of Parcels'!O25 -> 0.95527754 | M18: ='# and Assessed Value of Parcels'!H25/'# and Assessed Value of Parcels'!P25 -> 0.7164271 | N18: =(L18+M18)/2 -> 0.83585232 | O18: ='Tax Levies and EQ Tax Rates'!I25 -> 1.0413965e+08 | P18: =N18*O18 -> 87045366 | Q18: 103639 | R18: =P18/Q18 -> 839.89006 | S18: ='Tax Levies and EQ Tax Rates'!C25 -> 190553334 | T18: 14362 | U18: =S18/T18 -> 13267.883
A19: Monmouth | B19: Keansburg Borough | C19: =$B$5*R19 -> 3145.2065 | D19: =U19*$B$6 -> 1264.2511 | E19: =C19+D19 -> 4409.4575 | F19: =E19/(K19/100) -> 163479.66 | G19: 134718.75 | H19: =G19-F19 -> -28760.905 | I19: 183891.1 | J19: =I19-F19 -> 20411.448 | K19: ='Tax Levies and EQ Tax Rates'!O26 -> 2.6972516 | L19: ='# and Assessed Value of Parcels'!G26/'# and Assessed Value of Parcels'!O26 -> 0.96441281 | M19: ='# and Assessed Value of Parcels'!H26/'# and Assessed Value of Parcels'!P26 -> 0.88303144 | N19: =(L19+M19)/2 -> 0.92372213 | O19: ='Tax Levies and EQ Tax Rates'!I26 -> 12047538 | P19: =N19*O19 -> 11128578 | Q19: 9755 | R19: =P19/Q19 -> 1140.8076 | S19: ='Tax Levies and EQ Tax Rates'!C26 -> 5294981 | T19: 1780 | U19: =S19/T19 -> 2974.7084
A20: Monmouth | B20: Manalapan Township | C20: =$B$5*R20 -> 1593.4249 | D20: =U20*$B$6 -> 5811.8988 | E20: =C20+D20 -> 7405.3237 | F20: =E20/(K20/100) -> 457489.09 | G20: 292062.5 | H20: =G20-F20 -> -165426.59 | I20: 480487.37 | J20: =I20-F20 -> 22998.28 | K20: ='Tax Levies and EQ Tax Rates'!O27 -> 1.6186886 | L20: ='# and Assessed Value of Parcels'!G27/'# and Assessed Value of Parcels'!O27 -> 0.97272104 | M20: ='# and Assessed Value of Parcels'!H27/'# and Assessed Value of Parcels'!P27 -> 0.9220575 | N20: =(L20+M20)/2 -> 0.94738927 | O20: ='Tax Levies and EQ Tax Rates'!I27 -> 24954149 | P20: =N20*O20 -> 23641293 | Q20: 40905 | R20: =P20/Q20 -> 577.95608 | S20: ='Tax Levies and EQ Tax Rates'!C27 -> 66693248 | T20: 4877 | U20: =S20/T20 -> 13675.056
A21: Passaic | B21: Paterson City | C21: =$B$5*R21 -> 2099.9796 | D21: =U21*$B$6 -> 686.56224 | E21: =C21+D21 -> 2786.5418 | F21: =E21/(K21/100) -> 107841.82 | G21: 127704.12 | H21: =G21-F21 -> 19862.305 | I21: 259019.58 | J21: =I21-F21 -> 151177.77 | K21: ='Tax Levies and EQ Tax Rates'!O33 -> 2.5839159 | L21: ='# and Assessed Value of Parcels'!G33/'# and Assessed Value of Parcels'!O33 -> 0.82159481 | M21: ='# and Assessed Value of Parcels'!H33/'# and Assessed Value of Parcels'!P33 -> 0.65337602 | N21: =(L21+M21)/2 -> 0.73748542 | O21: ='Tax Levies and EQ Tax Rates'!I33 -> 1.6497449e+08 | P21: =N21*O21 -> 1.2166628e+08 | Q21: 159732 | R21: =P21/Q21 -> 761.69008 | S21: ='Tax Levies and EQ Tax Rates'!C33 -> 50970381 | T21: 31552 | U21: =S21/T21 -> 1615.4406
A22: Passaic | B22: Pompton Lakes Borough | C22: =$B$5*R22 -> 2449.0171 | D22: =U22*$B$6 -> 5631.4716 | E22: =C22+D22 -> 8080.4887 | F22: =E22/(K22/100) -> 283432.71 | G22: 277978.02 | H22: =G22-F22 -> -5454.6889 | I22: 297009.71 | J22: =I22-F22 -> 13577.009 | K22: ='Tax Levies and EQ Tax Rates'!O34 -> 2.8509373 | L22: ='# and Assessed Value of Parcels'!G34/'# and Assessed Value of Parcels'!O34 -> 0.95521999 | M22: ='# and Assessed Value of Parcels'!H34/'# and Assessed Value of Parcels'!P34 -> 0.87552226 | N22: =(L22+M22)/2 -> 0.91537113 | O22: ='Tax Levies and EQ Tax Rates'!I34 -> 10797816 | P22: =N22*O22 -> 9884009 | Q22: 11127 | R22: =P22/Q22 -> 888.29056 | S22: ='Tax Levies and EQ Tax Rates'!C34 -> 25639759 | T22: 1935 | U22: =S22/T22 -> 13250.521
A23: Passaic | B23: Wayne Township | C23: =$B$5*R23 -> 2768.1416 | D23: =U23*$B$6 -> 8457.9535 | E23: =C23+D23 -> 11226.095 | F23: =E23/(K23/100) -> 552668.28 | G23: 153319.37 | H23: =G23-F23 -> -399348.9 | I23: 477846.14 | J23: =I23-F23 -> -74822.141 | K23: ='Tax Levies and EQ Tax Rates'!O35 -> 2.0312538 | L23: ='# and Assessed Value of Parcels'!G35/'# and Assessed Value of Parcels'!O35 -> 0.95973428 | M23: ='# and Assessed Value of Parcels'!H35/'# and Assessed Value of Parcels'!P35 -> 0.74630979 | N23: =(L23+M23)/2 -> 0.85302204 | O23: ='Tax Levies and EQ Tax Rates'!I35 -> 64546529 | P23: =N23*O23 -> 55059612 | Q23: 54838 | R23: =P23/Q23 -> 1004.0412 | S23: ='Tax Levies and EQ Tax Rates'!C35 -> 156760706 | T23: 7877 | U23: =S23/T23 -> 19901.067
A24: Somerset | B24: Franklin Township | C24: =$B$5*R24 -> 1514.177 | D24: =U24*$B$6 -> 7590.1128 | E24: =C24+D24 -> 9104.2898 | F24: =E24/(K24/100) -> 560897.18 | G24: 141634.5 | H24: =G24-F24 -> -419262.68 | I24: 369483.93 | J24: =I24-F24 -> -191413.25 | K24: ='Tax Levies and EQ Tax Rates'!O38 -> 1.6231655 | L24: ='# and Assessed Value of Parcels'!G38/'# and Assessed Value of Parcels'!O38 -> 0.96646123 | M24: ='# and Assessed Value of Parcels'!H38/'# and Assessed Value of Parcels'!P38 -> 0.74002785 | N24: =(L24+M24)/2 -> 0.85324454 | O24: ='Tax Levies and EQ Tax Rates'!I38 -> 44004169 | P24: =N24*O24 -> 37546317 | Q24: 68364 | R24: =P24/Q24 -> 549.21182 | S24: ='Tax Levies and EQ Tax Rates'!C38 -> 151105752 | T24: 8461 | U24: =S24/T24 -> 17859.089
A25: Somerset | B25: Manville Borough | C25: =$B$5*R25 -> 2179.8075 | D25: =U25*$B$6 -> 4022.8578 | E25: =C25+D25 -> 6202.6653 | F25: =E25/(K25/100) -> 235097.44 | G25: 194522.93 | H25: =G25-F25 -> -40574.503 | I25: 253303.85 | J25: =I25-F25 -> 18206.418 | K25: ='Tax Levies and EQ Tax Rates'!O39 -> 2.6383382 | L25: ='# and Assessed Value of Parcels'!G39/'# and Assessed Value of Parcels'!O39 -> 0.95111773 | M25: ='# and Assessed Value of Parcels'!H39/'# and Assessed Value of Parcels'!P39 -> 0.86385135 | N25: =(L25+M25)/2 -> 0.90748454 | O25: ='Tax Levies and EQ Tax Rates'!I39 -> 9542787.2 | P25: =N25*O25 -> 8659931.8 | Q25: 10953 | R25: =P25/Q25 -> 790.64474 | S25: ='Tax Levies and EQ Tax Rates'!C39 -> 15656016 | T25: 1654 | U25: =S25/T25 -> 9465.5478
A26: Union | B26: Linden City | C26: =$B$5*R26 -> 2837.4457 | D26: =U26*$B$6 -> 6081.6774 | E26: =C26+D26 -> 8919.1231 | F26: =E26/(K26/100) -> 384214.47 | G26: 208675.72 | H26: =G26-F26 -> -175538.75 | I26: 326673.73 | J26: =I26-F26 -> -57540.74 | K26: ='Tax Levies and EQ Tax Rates'!O40 -> 2.3213918 | L26: ='# and Assessed Value of Parcels'!G40/'# and Assessed Value of Parcels'!O40 -> 0.90298507 | M26: ='# and Assessed Value of Parcels'!H40/'# and Assessed Value of Parcels'!P40 -> 0.53546516 | N26: =(L26+M26)/2 -> 0.71922512 | O26: ='Tax Levies and EQ Tax Rates'!I40 -> 62587105 | P26: =N26*O26 -> 45014218 | Q26: 43738 | R26: =P26/Q26 -> 1029.1787 | S26: ='Tax Levies and EQ Tax Rates'!C40 -> 94215916 | T26: 6584 | U26: =S26/T26 -> 14309.829
A27: Union | B27: Rahway City | C27: =$B$5*R27 -> 3051.4642 | D27: =U27*$B$6 -> 4663.7175 | E27: =C27+D27 -> 7715.1818 | F27: =E27/(K27/100) -> 267382.16 | G27: 264304.56 | H27: =G27-F27 -> -3077.5992 | I27: 271614.82 | J27: =I27-F27 -> 4232.6661 | K27: ='Tax Levies and EQ Tax Rates'!O41 -> 2.8854512 | L27: ='# and Assessed Value of Parcels'!G41/'# and Assessed Value of Parcels'!O41 -> 0.94367816 | M27: ='# and Assessed Value of Parcels'!H41/'# and Assessed Value of Parcels'!P41 -> 0.73460248 | N27: =(L27+M27)/2 -> 0.83914032 | O27: ='Tax Levies and EQ Tax Rates'!I41 -> 38983658 | P27: =N27*O27 -> 32712759 | Q27: 29556 | R27: =P27/Q27 -> 1106.806 | S27: ='Tax Levies and EQ Tax Rates'!C41 -> 45342308 | T27: 4132 | U27: =S27/T27 -> 10973.453
C28: =AVERAGE(C10:C27) -> 2243.8224 | D28: =AVERAGE(D10:D27) -> 4665.0767 | E28: =AVERAGE(E10:E27) -> 6908.8991 | F28: =AVERAGE(F10:F27) -> 311419.48 | G28: =AVERAGE(G10:G27) -> 203543.88 | H28: =AVERAGE(H10:H27) -> -107875.59 | I28: =AVERAGE(I10:I27) -> 314676.7 | J28: =AVERAGE(J10:J27) -> 3257.2281 | ... U28: =AVERAGE(U10:U27) -> 10976.651

Sheet (SFD 3 Bed) Muni Break Even
A1: 2020 Municipal Break Even Analysis for Single Family Detached (3 Bedroom) in Selected NJ Communities
A3: Single Family Detached (3 Bedroom) Multipliers
A4: Category | B4: Multiplier
A5: Household Size | B5: 2.757
A6: School Age Children | B6: 0.425
A8: Location | C8: 3 Bedroom Single Family Detached Municipal "Break Even Analysis" | E8: Fiscal Analysis | I8: Municipal Fiscal Impact Analysis
A9: County | B9: Municipality | C9: Municipal Tax Supported Cost | D9: Market Value "Break Even" | E9: Average Real (2020) Market Value of Buyout Properties | F9: Fiscal Surplus or Deficit (Based on Average Buyout Market Value) | G9: Average 2020 Residential Value in Buyout Community | H9: Fiscal Surplus or Deficit (Based on Average Residential Value) | I9: Municipal Equalized Property Tax Rate | J9: Percent of Total Parcels that are Residential | K9: Percent of Total Assessed Value that is Residential | L9: Average of Residential Parcels % and Assessed Value % | M9: Total Municipal Property Tax Levy | N9: Estimated Residential Share of Total Municipal Property Tax Levy | O9: 2020 Municipal Population | P9: 2020 Municipal Property Tax Supported Cost Per Person
A10: Atlantic | B10: Pleasantville City | C10: =$B$5*P10 -> 2629.6625 | D10: =C10/(I10/100) -> 85826.192 | E10: 60235 | F10: =E10-D10 -> -25591.192 | G10: 98363 | H10: =G10-D10 -> 12536.808 | I10: 3.0639394 | J10: ='# and Assessed Value of Parcels'!G5/'# and Assessed Value of Parcels'!O5 -> 0.92172813 | K10: ='# and Assessed Value of Parcels'!H5/'# and Assessed Value of Parcels'!P5 -> 0.73101366 | L10: =(J10+K10)/2 -> 0.8263709 | M10: ='Tax Levies and EQ Tax Rates'!I5 -> 23810385 | N10: =L10*M10 -> 19676209 | O10: 20629 | P10: =N10/O10 -> 953.81304
A11: Bergen | B11: Hillsdale Borough | C11: =$B$5*P11 -> 2609.5499 | D11: =C11/(I11/100) -> 486674.59 | E11: 221888 | F11: =E11-D11 -> -264786.59 | G11: 524210 | H11: =G11-D11 -> 37535.415 | I11: 0.53620016 | J11: ='# and Assessed Value of Parcels'!G6/'# and Assessed Value of Parcels'!O6 -> 0.96785506 | K11: ='# and Assessed Value of Parcels'!H6/'# and Assessed Value of Parcels'!P6 -> 0.93507138 | L11: =(J11+K11)/2 -> 0.95146322 | M11: ='Tax Levies and EQ Tax Rates'!I6 -> 10090281 | N11: =L11*M11 -> 9600531.2 | O11: 10143 | P11: =N11/O11 -> 946.51792
A12: Bergen | B12: New Milford Borough | C12: =$B$5*P12 -> 2706.2841 | D12: =C12/(I12/100) -> 324270.86 | E12: 373724 | F12: =E12-D12 -> 49453.139 | G12: 426888 | H12: =G12-D12 -> 102617.14 | I12: 0.83457519 | J12: ='# and Assessed Value of Parcels'!G7/'# and Assessed Value of Parcels'!O7 -> 0.98144233 | K12: ='# and Assessed Value of Parcels'!H7/'# and Assessed Value of Parcels'!P7 -> 0.94433259 | L12: =(J12+K12)/2 -> 0.96288746 | M12: ='Tax Levies and EQ Tax Rates'!I7 -> 17251960 | N12: =L12*M12 -> 16611696 | O12: 16923 | P12: =N12/O12 -> 981.6047
A13: Bergen | B13: Oakland Borough | C13: =$B$5*P13 -> 3082.9716 | D13: =C13/(I13/100) -> 511042.17 | E13: 366173 | F13: =E13-D13 -> -144869.17 | G13: 498789 | H13: =G13-D13 -> -12253.17 | I13: 0.60327146 | J13: ='# and Assessed Value of Parcels'!G8/'# and Assessed Value of Parcels'!O8 -> 0.9566732 | K13: ='# and Assessed Value of Parcels'!H8/'# and Assessed Value of Parcels'!P8 -> 0.84635298 | L13: =(J13+K13)/2 -> 0.90151309 | M13: ='Tax Levies and EQ Tax Rates'!I8 -> 15812581 | N13: =L13*M13 -> 14255249 | O13: 12748 | P13: =N13/O13 -> 1118.2342
A14: Bergen | B14: Westwood Borough | C14: =$B$5*P14 -> 3210.5266 | D14: =C14/(I14/100) -> 437612.4 | E14: 468655 | F14: =E14-D14 -> 31042.605 | G14: 459467 | H14: =G14-D14 -> 21854.605 | I14: 0.73364618 | J14: ='# and Assessed Value of Parcels'!G9/'# and Assessed Value of Parcels'!O9 -> 0.91940211 | K14: ='# and Assessed Value of Parcels'!H9/'# and Assessed Value of Parcels'!P9 -> 0.75552222 | L14: =(J14+K14)/2 -> 0.83746217 | M14: ='Tax Levies and EQ Tax Rates'!I9 -> 15687741 | N14: =L14*M14 -> 13137890 | O14: 11282 | P14: =N14/O14 -> 1164.5
A15: Burlington | B15: Lumberton Township | C15: =$B$5*P15 -> 1077.5897 | D15: =C15/(I15/100) -> 276189.13 | E15: 466392.16 | F15: =E15-D15 -> 190203.03 | G15: 306836 | H15: =G15-D15 -> 30646.87 | I15: 0.39016368 | J15: ='# and Assessed Value of Parcels'!G10/'# and Assessed Value of Parcels'!O10 -> 0.96040113 | K15: ='# and Assessed Value of Parcels'!H10/'# and Assessed Value of Parcels'!P10 -> 0.85301722 | L15: =(J15+K15)/2 -> 0.90670917 | M15: ='Tax Levies and EQ Tax Rates'!I10 -> 5518999.9 | N15: =L15*M15 -> 5004127.9 | O15: 12803 | P15: =N15/O15 -> 390.85588
A16: Burlington | B16: Medford Township | C16: =$B$5*P16 -> 1379.4002 | D16: =C16/(I16/100) -> 365342.55 | E16: 109349.33 | F16: =E16-D16 -> -255993.22 | G16: 370784 | H16: =G16-D16 -> 5441.4455 | I16: 0.37756351 | J16: ='# and Assessed Value of Parcels'!G11/'# and Assessed Value of Parcels'!O11 -> 0.95851299 | K16: ='# and Assessed Value of Parcels'!H11/'# and Assessed Value of Parcels'!P11 -> 0.91282275 | L16: =(J16+K16)/2 -> 0.93566787 | M16: ='Tax Levies and EQ Tax Rates'!I11 -> 13099198 | N16: =L16*M16 -> 12256498 | O16: 24497 | P16: =N16/O16 -> 500.32651
A17: Burlington | B17: Pemberton Township | C17: =$B$5*P17 -> 1499.5368 | D17: =C17/(I17/100) -> 147910.57 | E17: 93906.75 | F17: =E17-D17 -> -54003.816 | G17: 166312 | H17: =G17-D17 -> 18401.434 | I17: 1.0138132 | J17: ='# and Assessed Value of Parcels'!G12/'# and Assessed Value of Parcels'!O12 -> 0.98128309 | K17: ='# and Assessed Value of Parcels'!H12/'# and Assessed Value of Parcels'!P12 -> 0.9332896 | L17: =(J17+K17)/2 -> 0.95728635 | M17: ='Tax Levies and EQ Tax Rates'!I12 -> 15285485 | N17: =L17*M17 -> 14632586 | O17: 26903 | P17: =N17/O17 -> 543.90165
A18: Burlington | B18: Southampton Township | C18: =$B$5*P18 -> 1061.9192 | D18: =C18/(I18/100) -> 313012.69 | E18: 131465.05 | F18: =E18-D18 -> -181547.64 | G18: 238534 | H18: =G18-D18 -> -74478.694 | I18: 0.33925754 | J18: ='# and Assessed Value of Parcels'!G13/'# and Assessed Value of Parcels'!O13 -> 0.96051204 | K18: ='# and Assessed Value of Parcels'!H13/'# and Assessed Value of Parcels'!P13 -> 0.90183161 | L18: =(J18+K18)/2 -> 0.93117183 | M18: ='Tax Levies and EQ Tax Rates'!I13 -> 4267546.8 | N18: =L18*M18 -> 3973819.4 | O18: 10317 | P18: =N18/O18 -> 385.17198
A19: Cumberland | B19: Downe Township | C19: =$B$5*P19 -> 941.32413 | D19: =C19/(I19/100) -> 247311.12 | E19: 98620.342 | F19: =E19-D19 -> -148690.78 | G19: 118489 | H19: =G19-D19 -> -128822.12 | I19: 0.38062345 | J19: ='# and Assessed Value of Parcels'!G14/'# and Assessed Value of Parcels'!O14 -> 0.94935452 | K19: ='# and Assessed Value of Parcels'!H14/'# and Assessed Value of Parcels'!P14 -> 0.95309492 | L19: =(J19+K19)/2 -> 0.95122472 | M19: ='Tax Levies and EQ Tax Rates'!I14 -> 502154.1 | N19: =L19*M19 -> 477661.39 | O19: 1399 | P19: =N19/O19 -> 341.43059
A20: Cumberland | B20: Fairfield Township | C20: =$B$5*P20 -> 631.91841 | D20: =C20/(I20/100) -> 129279.22 | E20: 87057.657 | F20: =E20-D20 -> -42221.565 | G20: 142843 | H20: =G20-D20 -> 13563.778 | I20: 0.48880122 | J20: ='# and Assessed Value of Parcels'!G15/'# and Assessed Value of Parcels'!O15 -> 0.95576808 | K20: ='# and Assessed Value of Parcels'!H15/'# and Assessed Value of Parcels'!P15 -> 0.9003797 | L20: =(J20+K20)/2 -> 0.92807389 | M20: ='Tax Levies and EQ Tax Rates'!I15 -> 1369687.7 | N20: =L20*M20 -> 1271171.4 | O20: 5546 | P20: =N20/O20 -> 229.20508
A21: Cumberland | B21: Lawrence Township | C21: =$B$5*P21 -> 1042.647 | D21: =C21/(I21/100) -> 191227.92 | E21: 36085 | F21: =E21-D21 -> -155142.92 | G21: 165078 | H21: =G21-D21 -> -26149.921 | I21: 0.54523786 | J21: ='# and Assessed Value of Parcels'!G16/'# and Assessed Value of Parcels'!O16 -> 0.96660808 | K21: ='# and Assessed Value of Parcels'!H16/'# and Assessed Value of Parcels'!P16 -> 0.93631576 | L21: =(J21+K21)/2 -> 0.95146192 | M21: ='Tax Levies and EQ Tax Rates'!I16 -> 1227003.4 | N21: =L21*M21 -> 1167447 | O21: 3087 | P21: =N21/O21 -> 378.18173
A22: Essex | B22: Fairfield Township | C22: =$B$5*P22 -> 3424.9496 | D22: =C22/(I22/100) -> 787752.69 | E22: 219689 | F22: =E22-D22 -> -568063.69 | G22: 603218.44 | H22: =G22-D22 -> -184534.25 | I22: 0.43477472 | J22: ='[1]# and Assessed Value of Parcels'!G17/'[1]# and Assessed Value of Parcels'!O17 -> 0.78907204 | K22: ='[1]# and Assessed Value of Parcels'!H17/'[1]# and Assessed Value of Parcels'!P17 -> 0.44402102 | L22: =(J22+K22)/2 -> 0.61654653 | M22: ='[1]Tax Levies and EQ Tax Rates'!I17 -> 15861222 | N22: =L22*M22 -> 9779181.4 | O22: 7872 | P22: =N22/O22 -> 1242.2741
A23: Essex | B23: Newark City | C23: =$B$5*P23 -> 1545.9463 | D23: =C23/(I23/100) -> 91834.175 | E23: 164529.67 | F23: =E23-D23 -> 72695.492 | G23: 206835 | H23: =G23-D23 -> 115000.83 | I23: 1.6834106 | J23: ='# and Assessed Value of Parcels'!G18/'# and Assessed Value of Parcels'!O18 -> 0.84162884 | K23: ='# and Assessed Value of Parcels'!H18/'# and Assessed Value of Parcels'!P18 -> 0.54365223 | L23: =(J23+K23)/2 -> 0.69264054 | M23: ='Tax Levies and EQ Tax Rates'!I18 -> 252218004 | N23: =L23*M23 -> 1.7469641e+08 | O23: 311549 | P23: =N23/O23 -> 560.73495
A24: Hunterdon | B24: Lebanon Township | C24: =$B$5*P24 -> 1181.2888 | D24: =C24/(I24/100) -> 398624.01 | E24: 60691.5 | F24: =E24-D24 -> -337932.51 | G24: 379827 | H24: =G24-D24 -> -18797.013 | I24: 0.29634161 | J24: ='# and Assessed Value of Parcels'!G19/'# and Assessed Value of Parcels'!O19 -> 0.96383866 | K24: ='# and Assessed Value of Parcels'!H19/'# and Assessed Value of Parcels'!P19 -> 0.93906348 | L24: =(J24+K24)/2 -> 0.95145107 | M24: ='Tax Levies and EQ Tax Rates'!I19 -> 2789807.1 | N24: =L24*M24 -> 2654365 | O24: 6195 | P24: =N24/O24 -> 428.46893
A25: Middlesex | B25: East Brunswick Township | C25: =$B$5*P25 -> 2171.3074 | D25: =C25/(I25/100) -> 375428.3 | E25: 228185.83 | F25: =E25-D25 -> -147242.46 | G25: 380312 | H25: =G25-D25 -> 4883.7025 | I25: 0.57835476 | J25: ='# and Assessed Value of Parcels'!G20/'# and Assessed Value of Parcels'!O20 -> 0.95667524 | K25: ='# and Assessed Value of Parcels'!H20/'# and Assessed Value of Parcels'!P20 -> 0.81220548 | L25: =(J25+K25)/2 -> 0.88444036 | M25: ='Tax Levies and EQ Tax Rates'!I20 -> 44269380 | N25: =L25*M25 -> 39153626 | O25: 49715 | P25: =N25/O25 -> 787.56163
A26: Middlesex | B26: Old Bridge Township | C26: =$B$5*P26 -> 1449.0294 | D26: =C26/(I26/100) -> 328051.36 | E26: 131130.71 | F26: =E26-D26 -> -196920.64 | G26: 375525 | H26: =G26-D26 -> 47473.643 | I26: 0.44170809 | J26: ='# and Assessed Value of Parcels'!G21/'# and Assessed Value of Parcels'!O21 -> 0.97122792 | K26: ='# and Assessed Value of Parcels'!H21/'# and Assessed Value of Parcels'!P21 -> 0.88589383 | L26: =(J26+K26)/2 -> 0.92856088 | M26: ='Tax Levies and EQ Tax Rates'!I21 -> 37853002 | N26: =L26*M26 -> 35148817 | O26: 66876 | P26: =N26/O26 -> 525.58193
A27: Middlesex | B27: Middlesex Borough | C27: =$B$5*P27 -> 2290.0211 | D27: =C27/(I27/100) -> 281849.57 | E27: 306079.81 | F27: =E27-D27 -> 24230.246 | G27: 324883 | H27: =G27-D27 -> 43033.434 | I27: 0.81249766 | J27: ='# and Assessed Value of Parcels'!G22/'# and Assessed Value of Parcels'!O22 -> 0.92460317 | K27: ='# and Assessed Value of Parcels'!H22/'# and Assessed Value of Parcels'!P22 -> 0.82398227 | L27: =(J27+K27)/2 -> 0.87429272 | M27: ='Tax Levies and EQ Tax Rates'!I22 -> 13904913 | N27: =L27*M27 -> 12156964 | O27: 14636 | P27: =N27/O27 -> 830.62065
A28: Middlesex | B28: Sayreville Borough | C28: =$B$5*P28 -> 1959.3985 | D28: =C28/(I28/100) -> 289963.5 | E28: 208675.08 | F28: =E28-D28 -> -81288.419 | G28: 330955 | H28: =G28-D28 -> 40991.501 | I28: 0.67573971 | J28: ='# and Assessed Value of Parcels'!G23/'# and Assessed Value of Parcels'!O23 -> 0.96279666 | K28: ='# and Assessed Value of Parcels'!H23/'# and Assessed Value of Parcels'!P23 -> 0.85286918 | L28: =(J28+K28)/2 -> 0.90783292 | M28: ='Tax Levies and EQ Tax Rates'!I23 -> 35498458 | N28: =L28*M28 -> 32226669 | O28: 45345 | P28: =N28/O28 -> 710.69949
A29: Middlesex | B29: South River Borough | C29: =$B$5*P29 -> 1682.9131 | D29: =C29/(I29/100) -> 238510.28 | E29: 163469.67 | F29: =E29-D29 -> -75040.613 | G29: 293470 | H29: =G29-D29 -> 54959.721 | I29: 0.70559352 | J29: ='# and Assessed Value of Parcels'!G24/'# and Assessed Value of Parcels'!O24 -> 0.95376862 | K29: ='# and Assessed Value of Parcels'!H24/'# and Assessed Value of Parcels'!P24 -> 0.87694473 | L29: =(J29+K29)/2 -> 0.91535668 | M29: ='Tax Levies and EQ Tax Rates'!I24 -> 10748447 | N29: =L29*M29 -> 9838662.7 | O29: 16118 | P29: =N29/O29 -> 610.41461
A30: Middlesex | B30: Woodbridge Township | C30: =$B$5*P30 -> 2315.5769 | D30: =C30/(I30/100) -> 280090.29 | E30: 232839.67 | F30: =E30-D30 -> -47250.624 | G30: 307620 | H30: =G30-D30 -> 27529.705 | I30: 0.82672514 | J30: ='# and Assessed Value of Parcels'!G25/'# and Assessed Value of Parcels'!O25 -> 0.95527754 | K30: ='# and Assessed Value of Parcels'!H25/'# and Assessed Value of Parcels'!P25 -> 0.7164271 | L30: =(J30+K30)/2 -> 0.83585232 | M30: ='Tax Levies and EQ Tax Rates'!I25 -> 1.0413965e+08 | N30: =L30*M30 -> 87045366 | O30: 103639 | P30: =N30/O30 -> 839.89006
A31: Monmouth | B31: Keansburg Borough | C31: =$B$5*P31 -> 3145.2065 | D31: =C31/(I31/100) -> 167857.82 | E31: 134718.75 | F31: =E31-D31 -> -33139.069 | G31: 183891 | H31: =G31-D31 -> 16033.181 | I31: 1.8737325 | J31: ='# and Assessed Value of Parcels'!G26/'# and Assessed Value of Parcels'!O26 -> 0.96441281 | K31: ='# and Assessed Value of Parcels'!H26/'# and Assessed Value of Parcels'!P26 -> 0.88303144 | L31: =(J31+K31)/2 -> 0.92372213 | M31: ='Tax Levies and EQ Tax Rates'!I26 -> 12047538 | N31: =L31*M31 -> 11128578 | O31: 9755 | P31: =N31/O31 -> 1140.8076
A32: Monmouth | B32: Manalapan Township | C32: =$B$5*P32 -> 1593.4249 | D32: =C32/(I32/100) -> 477471.67 | E32: 292062.5 | F32: =E32-D32 -> -185409.17 | G32: 480487 | H32: =G32-D32 -> 3015.3312 | I32: 0.33372135 | J32: ='# and Assessed Value of Parcels'!G27/'# and Assessed Value of Parcels'!O27 -> 0.97272104 | K32: ='# and Assessed Value of Parcels'!H27/'# and Assessed Value of Parcels'!P27 -> 0.9220575 | L32: =(J32+K32)/2 -> 0.94738927 | M32: ='Tax Levies and EQ Tax Rates'!I27 -> 24954149 | N32: =L32*M32 -> 23641293 | O32: 40905 | P32: =N32/O32 -> 577.95608
A33: Monmouth | B33: Ocean Township | C33: =$B$5*P33 -> 2094.8251 | D33: =C33/(I33/100) -> 517601.17 | E33: 899998.8 | F33: =E33-D33 -> 382397.63 | G33: 542012 | H33: =G33-D33 -> 24410.83 | I33: 0.404718 | J33: ='# and Assessed Value of Parcels'!G28/'# and Assessed Value of Parcels'!O28 -> 0.95530169 | K33: ='# and Assessed Value of Parcels'!H28/'# and Assessed Value of Parcels'!P28 -> 0.88451081 | L33: =(J33+K33)/2 -> 0.91990625 | M33: ='Tax Levies and EQ Tax Rates'!I28 -> 22856408 | N33: =L33*M33 -> 21025753 | O33: 27672 | P33: =N33/O33 -> 759.82049
A34: Monmouth | B34: Sea Bright Borough | C34: =$B$5*P34 -> 7782.1828 | D34: =C34/(I34/100) -> 1515173.6 | E34: 1438976 | F34: =E34-D34 -> -76197.631 | G34: 697318 | H34: =G34-D34 -> -817855.63 | I34: 0.51361656 | J34: ='# and Assessed Value of Parcels'!G29/'# and Assessed Value of Parcels'!O29 -> 0.9358047 | K34: ='# and Assessed Value of Parcels'!H29/'# and Assessed Value of Parcels'!P29 -> 0.81959946 | L34: =(J34+K34)/2 -> 0.87770208 | M34: ='Tax Levies and EQ Tax Rates'!I29 -> 4660000 | N34: =L34*M34 -> 4090091.7 | O34: 1449 | P34: =N34/O34 -> 2822.6996
... A47: Warren | B47: Harmony Township | C47: =$B$5*P47 -> 1243.1437 | D47: =C47/(I47/100) -> 433268.6 | E47: 114179.2 | F47: =E47-D47 -> -319089.39 | G47: 240185 | H47: =G47-D47 -> -193083.6 | I47: 0.28692219 | J47: ='# and Assessed Value of Parcels'!G42/'# and Assessed Value of Parcels'!O42 -> 0.95134062 | K47: ='# and Assessed Value of Parcels'!H42/'# and Assessed Value of Parcels'!P42 -> 0.44542234 | L47: =(J47+K47)/2 -> 0.69838148 | M47: ='Tax Levies and EQ Tax Rates'!I42 -> 1616042.3 | N47: =L47*M47 -> 1128614 | O47: 2503 | P47: =N47/O47 -> 450.90451
C48: =AVERAGE(C10:C47) -> 2219.9955 | D48: =AVERAGE(D10:D47) -> 359859.61 | E48: =AVERAGE(E10:E47) -> 248533.53 | F48: =AVERAGE(F10:F47) -> -111326.07 | G48: =AVERAGE(G10:G47) -> 345015.35 | H48: =AVERAGE(H10:H47) -> -14844.252 | I48: =AVERAGE(I10:I47) -> 0.7753169 | J48: =AVERAGE(J10:J47) -> 0.94289016 | ... P48: =AVERAGE(P10:P47) -> 805.22145

Sheet (SFA 3 Bed) Break Even
A1: 2020 Break Even Analysis for Single Family Attached (3 Bedroom) in Selected NJ Communities
A3: Single Family Attached (3 Bedroom) Multipliers
A4: Category | B4: Multiplier
A5: Household Size | B5: 2.899
A6: School Age Children | B6: 0.564
A8: Location | C8: 2.5 Bedroom Single Family Attached "Break Even Analysis" | G8: Fiscal Analysis | M8: School and Municipal Fiscal Impact Analysis
A9: County | B9: Municipality | C9: Municipal Tax Supported Cost | D9: School Tax Supported Cost | E9: Total Tax Supported Cost | F9: Market Value "Break Even" | G9: Adjusted Average Real (2020) Market Value of Buyout Properties | H9: Average Real (2020) Market Value of Buyout Properties | I9: Fiscal Surplus or Deficit (Based on Average Buyout Market Value) | J9: Adjusted Average 2020 Residential Value in Buyout Community | K9: Average 2020 Residential Value in Buyout Community | L9: Fiscal Surplus or Deficit (Based on Average Residential Value) | M9: Total Municipal + School Equalized Property Tax Rate | N9: Percent of Total Parcels that are Residential | O9: Percent of Total Assessed Value that is Residential | P9: Average of Residential Parcels % and Assessed Value % | Q9: Total Municipal Property Tax Levy | R9: Estimated Residential Share of Total Municipal Property Tax Levy | S9: 2020 Municipal Population | T9: 2020 Municipal Property Tax Supported Cost Per Person | U9: Total School Property Tax Levy | V9: 2020 Total School Enrollment | W9: 2020 School Property Tax Supported Cost Per Pupil
A10: Atlantic | B10: Pleasantville City | C10: =$B$5*T10 -> 2765.104 | D10: =W10*$B$6 -> 1311.4548 | E10: =C10+D10 -> 4076.5588 | F10: =E10/(M10/100) -> 93278.14 | G10: =0.9*H10 -> 54211.5 | H10: 60235 | I10: =H10-F10 -> -33043.14 | J10: =0.9*K10 -> 88526.492 | K10: 98362.768 | L10: =K10-F10 -> 5084.6287 | M10: ='Tax Levies and EQ Tax Rates'!O5 -> 4.370326 | N10: ='# and Assessed Value of Parcels'!G5/'# and Assessed Value of Parcels'!O5 -> 0.92172813 | O10: ='# and Assessed Value of Parcels'!H5/'# and Assessed Value of Parcels'!P5 -> 0.73101366 | P10: =(N10+O10)/2 -> 0.8263709 | Q10: ='Tax Levies and EQ Tax Rates'!I5 -> 23810385 | R10: =P10*Q10 -> 19676209 | S10: 20629 | T10: =R10/S10 -> 953.81304 | U10: ='Tax Levies and EQ Tax Rates'!C5 -> 10152148 | V10: 4366 | W10: =U10/V10 -> 2325.2744
A11: Bergen | B11: New Milford Borough | C11: =$B$5*T11 -> 2845.672 | D11: =W11*$B$6 -> 8710.7237 | E11: =C11+D11 -> 11556.396 | F11: =E11/(M11/100) -> 455056.95 | G11: =0.9*H11 -> 336351.6 | H11: 373724 | I11: =H11-F11 -> -81332.953 | J11: =0.9*K11 -> 384199.28 | K11: 426888.09 | L11: =K11-F11 -> -28168.863 | M11: ='Tax Levies and EQ Tax Rates'!O7 -> 2.5395493 | N11: ='# and Assessed Value of Parcels'!G7/'# and Assessed Value of Parcels'!O7 -> 0.98144233 | O11: ='# and Assessed Value of Parcels'!H7/'# and Assessed Value of Parcels'!P7 -> 0.94433259 | P11: =(N11+O11)/2 -> 0.96288746 | Q11: ='Tax Levies and EQ Tax Rates'!I7 -> 17251960 | R11: =P11*Q11 -> 16611696 | S11: 16923 | T11: =R11/S11 -> 981.6047 | U11: ='Tax Levies and EQ Tax Rates'!C7 -> 35244453 | V11: 2282 | W11: =U11/V11 -> 15444.546
A12: Essex | B12: Newark City | C12: =$B$5*T12 -> 1625.5706 | D12: =W12*$B$6 -> 1273.8381 | E12: =C12+D12 -> 2899.4087 | F12: =E12/(M12/100) -> 109584 | G12: =0.9*H12 -> 148076.7 | H12: 164529.67 | I12: =H12-F12 -> 54945.666 | J12: =0.9*K12 -> 186151.52 | K12: 206835.02 | L12: =K12-F12 -> 97251.019 | M12: ='Tax Levies and EQ Tax Rates'!O18 -> 2.6458321 | N12: ='# and Assessed Value of Parcels'!G18/'# and Assessed Value of Parcels'!O18 -> 0.84162884 | O12: ='# and Assessed Value of Parcels'!H18/'# and Assessed Value of Parcels'!P18 -> 0.54365223 | P12: =(N12+O12)/2 -> 0.69264054 | Q12: ='Tax Levies and EQ Tax Rates'!I18 -> 252218004 | R12: =P12*Q12 -> 1.7469641e+08 | S12: 311549 | T12: =R12/S12 -> 560.73495 | U12: ='Tax Levies and EQ Tax Rates'!C18 -> 135819599 | V12: 60135 | W12: =U12/V12 -> 2258.5782
A13: Middlesex | B13: East Brunswick Township | C13: =$B$5*T13 -> 2283.1412 | D13: =W13*$B$6 -> 9222.9216 | E13: =C13+D13 -> 11506.063 | F13: =E13/(M13/100) -> 483801.25 | G13: =0.9*H13 -> 205367.25 | H13: 228185.83 | I13: =H13-F13 -> -255615.42 | J13: =0.9*K13 -> 342281.24 | K13: 380312.49 | L13: =K13-F13 -> -103488.77 | M13: ='Tax Levies and EQ Tax Rates'!O20 -> 2.3782623 | N13: ='# and Assessed Value of Parcels'!G20/'# and Assessed Value of Parcels'!O20 -> 0.95667524 | O13: ='# and Assessed Value of Parcels'!H20/'# and Assessed Value of Parcels'!P20 -> 0.81220548 | P13: =(N13+O13)/2 -> 0.88444036 | Q13: ='Tax Levies and EQ Tax Rates'!I20 -> 44269380 | R13: =P13*Q13 -> 39153626 | S13: 49715 | T13: =R13/S13 -> 787.56163 | U13: ='Tax Levies and EQ Tax Rates'!C20 -> 137771480 | V13: 8425 | W13: =U13/V13 -> 16352.698
A14: Middlesex | B14: Old Bridge Township | C14: =$B$5*T14 -> 1523.662 | D14: =W14*$B$6 -> 7448.4645 | E14: =C14+D14 -> 8972.1265 | F14: =E14/(M14/100) -> 532359.06 | G14: =0.9*H14 -> 118017.64 | H14: 131130.71 | I14: =H14-F14 -> -401228.35 | J14: =0.9*K14 -> 337972.55 | K14: 375525.05 | L14: =K14-F14 -> -156834.01 | M14: ='Tax Levies and EQ Tax Rates'!O21 -> 1.6853524 | N14: ='# and Assessed Value of Parcels'!G21/'# and Assessed Value of Parcels'!O21 -> 0.97122792 | O14: ='# and Assessed Value of Parcels'!H21/'# and Assessed Value of Parcels'!P21 -> 0.88589383 | P14: =(N14+O14)/2 -> 0.92856088 | Q14: ='Tax Levies and EQ Tax Rates'!I21 -> 37853002 | R14: =P14*Q14 -> 35148817 | S14: 66876 | T14: =R14/S14 -> 525.58193 | U14: ='Tax Levies and EQ Tax Rates'!C21 -> 106576433 | V14: 8070 | W14: =U14/V14 -> 13206.497
A15: Middlesex | B15: Middlesex Borough | C15: =$B$5*T15 -> 2407.9693 | D15: =W15*$B$6 -> 7313.0024 | E15: =C15+D15 -> 9720.9717 | F15: =E15/(M15/100) -> 412368.17 | G15: =0.9*H15 -> 275471.83 | H15: 306079.81 | I15: =H15-F15 -> -106288.36 | J15: =0.9*K15 -> 292394.56 | K15: 324882.84 | L15: =K15-F15 -> -87485.331 | M15: ='Tax Levies and EQ Tax Rates'!O22 -> 2.3573526 | N15: ='# and Assessed Value of Parcels'!G22/'# and Assessed Value of Parcels'!O22 -> 0.92460317 | O15: ='# and Assessed Value of Parcels'!H22/'# and Assessed Value of Parcels'!P22 -> 0.82398227 | P15: =(N15+O15)/2 -> 0.87429272 | Q15: ='Tax Levies and EQ Tax Rates'!I22 -> 13904913 | R15: =P15*Q15 -> 12156964 | S15: 14636 | T15: =R15/S15 -> 830.62065 | U15: ='Tax Levies and EQ Tax Rates'!C22 -> 26438319 | V15: 2039 | W15: =U15/V15 -> 12966.316
A16: Middlesex | B16: Sayreville Borough | C16: =$B$5*T16 -> 2060.3178 | D16: =W16*$B$6 -> 5793.1984 | E16: =C16+D16 -> 7853.5162 | F16: =E16/(M16/100) -> 398786.45 | G16: =0.9*H16 -> 187807.57 | H16: 208675.08 | I16: =H16-F16 -> -190111.37 | J16: =0.9*K16 -> 297859.28 | K16: 330954.76 | L16: =K16-F16 -> -67831.688 | M16: ='Tax Levies and EQ Tax Rates'!O23 -> 1.9693538 | N16: ='# and Assessed Value of Parcels'!G23/'# and Assessed Value of Parcels'!O23 -> 0.96279666 | O16: ='# and Assessed Value of Parcels'!H23/'# and Assessed Value of Parcels'!P23 -> 0.85286918 | P16: =(N16+O16)/2 -> 0.90783292 | Q16: ='Tax Levies and EQ Tax Rates'!I23 -> 35498458 | R16: =P16*Q16 -> 32226669 | S16: 45345 | T16: =R16/S16 -> 710.69949 | U16: ='Tax Levies and EQ Tax Rates'!C23 -> 67957093 | V16: 6616 | W16: =U16/V16 -> 10271.628
A17: Middlesex | B17: South River Borough | C17: =$B$5*T17 -> 1769.592 | D17: =W17*$B$6 -> 4208.3331 | E17: =C17+D17 -> 5977.925 | F17: =E17/(M17/100) -> 315150.96 | G17: =0.9*H17 -> 147122.7 | H17: 163469.67 | I17: =H17-F17 -> -151681.29 | J17: =0.9*K17 -> 264122.92 | K17: 293469.91 | L17: =K17-F17 -> -21681.046 | M17: ='Tax Levies and EQ Tax Rates'!O24 -> 1.896845 | N17: ='# and Assessed Value of Parcels'!G24/'# and Assessed Value of Parcels'!O24 -> 0.95376862 | O17: ='# and Assessed Value of Parcels'!H24/'# and Assessed Value of Parcels'!P24 -> 0.87694473 | P17: =(N17+O17)/2 -> 0.91535668 | Q17: ='Tax Levies and EQ Tax Rates'!I24 -> 10748447 | R17: =P17*Q17 -> 9838662.7 | S17: 16118 | T17: =R17/S17 -> 610.41461 | U17: ='Tax Levies and EQ Tax Rates'!C24 -> 18146571 | V17: 2432 | W17: =U17/V17 -> 7461.5835
A18: Middlesex | B18: Woodbridge Township | C18: =$B$5*T18 -> 2434.8413 | D18: =W18*$B$6 -> 7483.0859 | E18: =C18+D18 -> 9917.9272 | F18: =E18/(M18/100) -> 423941.65 | G18: =0.9*H18 -> 209555.7 | H18: 232839.67 | I18: =H18-F18 -> -191101.97 | J18: =0.9*K18 -> 276857.56 | K18: 307619.51 | L18: =K18-F18 -> -116322.14 | M18: ='Tax Levies and EQ Tax Rates'!O25 -> 2.3394558 | N18: ='# and Assessed Value of Parcels'!G25/'# and Assessed Value of Parcels'!O25 -> 0.95527754 | O18: ='# and Assessed Value of Parcels'!H25/'# and Assessed Value of Parcels'!P25 -> 0.7164271 | P18: =(N18+O18)/2 -> 0.83585232 | Q18: ='Tax Levies and EQ Tax Rates'!I25 -> 1.0413965e+08 | R18: =P18*Q18 -> 87045366 | S18: 103639 | T18: =R18/S18 -> 839.89006 | U18: ='Tax Levies and EQ Tax Rates'!C25 -> 190553334 | V18: 14362 | W18: =U18/V18 -> 13267.883
A19: Monmouth | B19: Keansburg Borough | C19: =$B$5*T19 -> 3307.2011 | D19: =W19*$B$6 -> 1677.7356 | E19: =C19+D19 -> 4984.9367 | F19: =E19/(M19/100) -> 184815.42 | G19: =0.9*H19 -> 121246.88 | H19: 134718.75 | I19: =H19-F19 -> -50096.666 | J19: =0.9*K19 -> 165501.99 | K19: 183891.1 | L19: =K19-F19 -> -924.31329 | M19: ='Tax Levies and EQ Tax Rates'!O26 -> 2.6972516 | N19: ='# and Assessed Value of Parcels'!G26/'# and Assessed Value of Parcels'!O26 -> 0.96441281 | O19: ='# and Assessed Value of Parcels'!H26/'# and Assessed Value of Parcels'!P26 -> 0.88303144 | P19: =(N19+O19)/2 -> 0.92372213 | Q19: ='Tax Levies and EQ Tax Rates'!I26 -> 12047538 | R19: =P19*Q19 -> 11128578 | S19: 9755 | T19: =R19/S19 -> 1140.8076 | U19: ='Tax Levies and EQ Tax Rates'!C26 -> 5294981 | V19: 1780 | W19: =U19/V19 -> 2974.7084
A20: Monmouth | B20: Manalapan Township | C20: =$B$5*T20 -> 1675.4947 | D20: =W20*$B$6 -> 7712.7316 | E20: =C20+D20 -> 9388.2262 | F20: =E20/(M20/100) -> 579989.65 | G20: =0.9*H20 -> 262856.25 | H20: 292062.5 | I20: =H20-F20 -> -287927.15 | J20: =0.9*K20 -> 432438.64 | K20: 480487.37 | L20: =K20-F20 -> -99502.278 | M20: ='Tax Levies and EQ Tax Rates'!O27 -> 1.6186886 | N20: ='# and Assessed Value of Parcels'!G27/'# and Assessed Value of Parcels'!O27 -> 0.97272104 | O20: ='# and Assessed Value of Parcels'!H27/'# and Assessed Value of Parcels'!P27 -> 0.9220575 | P20: =(N20+O20)/2 -> 0.94738927 | Q20: ='Tax Levies and EQ Tax Rates'!I27 -> 24954149 | R20: =P20*Q20 -> 23641293 | S20: 40905 | T20: =R20/S20 -> 577.95608 | U20: ='Tax Levies and EQ Tax Rates'!C27 -> 66693248 | V20: 4877 | W20: =U20/V20 -> 13675.056
A21: Passaic | B21: Paterson City | C21: =$B$5*T21 -> 2208.1395 | D21: =W21*$B$6 -> 911.10848 | E21: =C21+D21 -> 3119.248 | F21: =E21/(M21/100) -> 120717.86 | G21: =0.9*H21 -> 114933.71 | H21: 127704.12 | I21: =H21-F21 -> 6986.2576 | J21: =0.9*K21 -> 233117.62 | K21: 259019.58 | L21: =K21-F21 -> 138301.72 | M21: ='Tax Levies and EQ Tax Rates'!O33 -> 2.5839159 | N21: ='# and Assessed Value of Parcels'!G33/'# and Assessed Value of Parcels'!O33 -> 0.82159481 | O21: ='# and Assessed Value of Parcels'!H33/'# and Assessed Value of Parcels'!P33 -> 0.65337602 | P21: =(N21+O21)/2 -> 0.73748542 | Q21: ='Tax Levies and EQ Tax Rates'!I33 -> 1.6497449e+08 | R21: =P21*Q21 -> 1.2166628e+08 | S21: 159732 | T21: =R21/S21 -> 761.69008 | U21: ='Tax Levies and EQ Tax Rates'!C33 -> 50970381 | V21: 31552 | W21: =U21/V21 -> 1615.4406
A22: Passaic | B22: Pompton Lakes Borough | C22: =$B$5*T22 -> 2575.1543 | D22: =W22*$B$6 -> 7473.2941 | E22: =C22+D22 -> 10048.448 | F22: =E22/(M22/100) -> 352461.22 | G22: =0.9*H22 -> 250180.21 | H22: 277978.02 | I22: =H22-F22 -> -74483.206 | J22: =0.9*K22 -> 267308.74 | K22: 297009.71 | L22: =K22-F22 -> -55451.508 | M22: ='Tax Levies and EQ Tax Rates'!O34 -> 2.8509373 | N22: ='# and Assessed Value of Parcels'!G34/'# and Assessed Value of Parcels'!O34 -> 0.95521999 | O22: ='# and Assessed Value of Parcels'!H34/'# and Assessed Value of Parcels'!P34 -> 0.87552226 | P22: =(N22+O22)/2 -> 0.91537113 | Q22: ='Tax Levies and EQ Tax Rates'!I34 -> 10797816 | R22: =P22*Q22 -> 9884009 | S22: 11127 | T22: =R22/S22 -> 888.29056 | U22: ='Tax Levies and EQ Tax Rates'!C34 -> 25639759 | V22: 1935 | W22: =U22/V22 -> 13250.521
A23: Passaic | B23: Wayne Township | C23: =$B$5*T23 -> 2910.7155 | D23: =W23*$B$6 -> 11224.202 | E23: =C23+D23 -> 14134.917 | F23: =E23/(M23/100) -> 695871.57 | G23: =0.9*H23 -> 137987.44 | H23: 153319.37 | I23: =H23-F23 -> -542552.19 | J23: =0.9*K23 -> 430061.52 | K23: 477846.14 | L23: =K23-F23 -> -218025.43 | M23: ='Tax Levies and EQ Tax Rates'!O35 -> 2.0312538 | N23: ='# and Assessed Value of Parcels'!G35/'# and Assessed Value of Parcels'!O35 -> 0.95973428 | O23: ='# and Assessed Value of Parcels'!H35/'# and Assessed Value of Parcels'!P35 -> 0.74630979 | P23: =(N23+O23)/2 -> 0.85302204 | Q23: ='Tax Levies and EQ Tax Rates'!I35 -> 64546529 | R23: =P23*Q23 -> 55059612 | S23: 54838 | T23: =R23/S23 -> 1004.0412 | U23: ='Tax Levies and EQ Tax Rates'!C35 -> 156760706 | V23: 7877 | W23: =U23/V23 -> 19901.067
A24: Somerset | B24: Franklin Township | C24: =$B$5*T24 -> 1592.1651 | D24: =W24*$B$6 -> 10072.526 | E24: =C24+D24 -> 11664.691 | F24: =E24/(M24/100) -> 718638.42 | G24: =0.9*H24 -> 127471.05 | H24: 141634.5 | I24: =H24-F24 -> -577003.92 | J24: =0.9*K24 -> 332535.54 | K24: 369483.93 | L24: =K24-F24 -> -349154.49 | M24: ='Tax Levies and EQ Tax Rates'!O38 -> 1.6231655 | N24: ='# and Assessed Value of Parcels'!G38/'# and Assessed Value of Parcels'!O38 -> 0.96646123 | O24: ='# and Assessed Value of Parcels'!H38/'# and Assessed Value of Parcels'!P38 -> 0.74002785 | P24: =(N24+O24)/2 -> 0.85324454 | Q24: ='Tax Levies and EQ Tax Rates'!I38 -> 44004169 | R24: =P24*Q24 -> 37546317 | S24: 68364 | T24: =R24/S24 -> 549.21182 | U24: ='Tax Levies and EQ Tax Rates'!C38 -> 151105752 | V24: 8461 | W24: =U24/V24 -> 17859.089
A25: Somerset | B25: Manville Borough | C25: =$B$5*T25 -> 2292.0791 | D25: =W25*$B$6 -> 5338.5689 | E25: =C25+D25 -> 7630.648 | F25: =E25/(M25/100) -> 289221.76 | G25: =0.9*H25 -> 175070.64 | H25: 194522.93 | I25: =H25-F25 -> -94698.827 | J25: =0.9*K25 -> 227973.47 | K25: 253303.85 | L25: =K25-F25 -> -35917.906 | M25: ='Tax Levies and EQ Tax Rates'!O39 -> 2.6383382 | N25: ='# and Assessed Value of Parcels'!G39/'# and Assessed Value of Parcels'!O39 -> 0.95111773 | O25: ='# and Assessed Value of Parcels'!H39/'# and Assessed Value of Parcels'!P39 -> 0.86385135 | P25: =(N25+O25)/2 -> 0.90748454 | Q25: ='Tax Levies and EQ Tax Rates'!I39 -> 9542787.2 | R25: =P25*Q25 -> 8659931.8 | S25: 10953 | T25: =R25/S25 -> 790.64474 | U25: ='Tax Levies and EQ Tax Rates'!C39 -> 15656016 | V25: 1654 | W25: =U25/V25 -> 9465.5478
A26: Union | B26: Linden City | C26: =$B$5*T26 -> 2983.5891 | D26: =W26*$B$6 -> 8070.7437 | E26: =C26+D26 -> 11054.333 | F26: =E26/(M26/100) -> 476194.19 | G26: =0.9*H26 -> 187808.15 | H26: 208675.72 | I26: =H26-F26 -> -267518.47 | J26: =0.9*K26 -> 294006.36 | K26: 326673.73 | L26: =K26-F26 -> -149520.46 | M26: ='Tax Levies and EQ Tax Rates'!O40 -> 2.3213918 | N26: ='# and Assessed Value of Parcels'!G40/'# and Assessed Value of Parcels'!O40 -> 0.90298507 | O26: ='# and Assessed Value of Parcels'!H40/'# and Assessed Value of Parcels'!P40 -> 0.53546516 | P26: =(N26+O26)/2 -> 0.71922512 | Q26: ='Tax Levies and EQ Tax Rates'!I40 -> 62587105 | R26: =P26*Q26 -> 45014218 | S26: 43738 | T26: =R26/S26 -> 1029.1787 | U26: ='Tax Levies and EQ Tax Rates'!C40 -> 94215916 | V26: 6584 | W26: =U26/V26 -> 14309.829
A27: Union | B27: Rahway City | C27: =$B$5*T27 -> 3208.6307 | D27: =W27*$B$6 -> 6189.0275 | E27: =C27+D27 -> 9397.6582 | F27: =E27/(M27/100) -> 325691.11 | G27: =0.9*H27 -> 237874.1 | H27: 264304.56 | I27: =H27-F27 -> -61386.553 | J27: =0.9*K27 -> 244453.34 | K27: 271614.82 | L27: =K27-F27 -> -54076.288 | M27: ='Tax Levies and EQ Tax Rates'!O41 -> 2.8854512 | N27: ='# and Assessed Value of Parcels'!G41/'# and Assessed Value of Parcels'!O41 -> 0.94367816 | O27: ='# and Assessed Value of Parcels'!H41/'# and Assessed Value of Parcels'!P41 -> 0.73460248 | P27: =(N27+O27)/2 -> 0.83914032 | Q27: ='Tax Levies and EQ Tax Rates'!I41 -> 38983658 | R27: =P27*Q27 -> 32712759 | S27: 29556 | T27: =R27/S27 -> 1106.806 | U27: ='Tax Levies and EQ Tax Rates'!C41 -> 45342308 | V27: 4132 | W27: =U27/V27 -> 10973.453
C28: =AVERAGE(C10:C27) -> 2359.3911 | D28: =AVERAGE(D10:D27) -> 6190.8311 | E28: =AVERAGE(E10:E27) -> 8550.2222 | F28: =AVERAGE(F10:F27) -> 387107.1 | G28: =AVERAGE(G10:G27) -> 183189.5 | H28: =AVERAGE(H10:H27) -> 203543.88 | I28: =AVERAGE(I10:I27) -> -183563.22 | J28: =AVERAGE(J10:J27) -> 283209.03 | ... W28: =AVERAGE(W10:W27) -> 10976.651

Sheet (SFA 3 Bed) Muni Break Even
A1: 2020 Municipal Break Even Analysis for Single Family Attached (3 Bedroom) in Selected NJ Communities
A3: Single Family Attached (3 Bedroom) Multipliers
A4: Category | B4: Multiplier
A5: Household Size | B5: 2.899
A6: School Age Children | B6: 0.564
A8: Location | C8: 3 Bedroom Single Family Detached Municipal "Break Even Analysis" | E8: Fiscal Analysis | K8: Municipal Fiscal Impact Analysis
A9: County | B9: Municipality | C9: Municipal Tax Supported Cost | D9: Market Value "Break Even" | E9: Adjusted Average Real (2020) Market Value of Buyout Properties | F9: Average Real (2020) Market Value of Buyout Properties | G9: Fiscal Surplus or Deficit (Based on Average Buyout Market Value) | H9: Adjusted Average 2020 Residential Value in Buyout Community | I9: Average 2020 Residential Value in Buyout Community | J9: Fiscal Surplus or Deficit (Based on Average Residential Value) | K9: Municipal Equalized Property Tax Rate | L9: Percent of Total Parcels that are Residential | M9: Percent of Total Assessed Value that is Residential | N9: Average of Residential Parcels % and Assessed Value % | O9: Total Municipal Property Tax Levy | P9: Estimated Residential Share of Total Municipal Property Tax Levy | Q9: 2020 Municipal Population | R9: 2020 Municipal Property Tax Supported Cost Per Person
A10: Atlantic | B10: Pleasantville City | C10: =$B$5*R10 -> 2765.104 | D10: =C10/(K10/100) -> 90246.693 | E10: =0.9*F10 -> 54211.5 | F10: 60235 | G10: =F10-D10 -> -30011.693 | H10: =0.9*I10 -> 88526.7 | I10: 98363 | J10: =I10-D10 -> 8116.3072 | K10: 3.0639394 | L10: ='# and Assessed Value of Parcels'!G5/'# and Assessed Value of Parcels'!O5 -> 0.92172813 | M10: ='# and Assessed Value of Parcels'!H5/'# and Assessed Value of Parcels'!P5 -> 0.73101366 | N10: =(L10+M10)/2 -> 0.8263709 | O10: ='Tax Levies and EQ Tax Rates'!I5 -> 23810385 | P10: =N10*O10 -> 19676209 | Q10: 20629 | R10: =P10/Q10 -> 953.81304
A11: Bergen | B11: Hillsdale Borough | C11: =$B$5*R11 -> 2743.9554 | D11: =C11/(K11/100) -> 511740.89 | E11: =0.9*F11 -> 199699.2 | F11: 221888 | G11: =F11-D11 -> -289852.89 | H11: =0.9*I11 -> 471789 | I11: 524210 | J11: =I11-D11 -> 12469.114 | K11: 0.53620016 | L11: ='# and Assessed Value of Parcels'!G6/'# and Assessed Value of Parcels'!O6 -> 0.96785506 | M11: ='# and Assessed Value of Parcels'!H6/'# and Assessed Value of Parcels'!P6 -> 0.93507138 | N11: =(L11+M11)/2 -> 0.95146322 | O11: ='Tax Levies and EQ Tax Rates'!I6 -> 10090281 | P11: =N11*O11 -> 9600531.2 | Q11: 10143 | R11: =P11/Q11 -> 946.51792
A12: Bergen | B12: New Milford Borough | C12: =$B$5*R12 -> 2845.672 | D12: =C12/(K12/100) -> 340972.52 | E12: =0.9*F12 -> 336351.6 | F12: 373724 | G12: =F12-D12 -> 32751.484 | H12: =0.9*I12 -> 384199.2 | I12: 426888 | J12: =I12-D12 -> 85915.484 | K12: 0.83457519 | L12: ='# and Assessed Value of Parcels'!G7/'# and Assessed Value of Parcels'!O7 -> 0.98144233 | M12: ='# and Assessed Value of Parcels'!H7/'# and Assessed Value of Parcels'!P7 -> 0.94433259 | N12: =(L12+M12)/2 -> 0.96288746 | O12: ='Tax Levies and EQ Tax Rates'!I7 -> 17251960 | P12: =N12*O12 -> 16611696 | Q12: 16923 | R12: =P12/Q12 -> 981.6047
A13: Bergen | B13: Oakland Borough | C13: =$B$5*R13 -> 3241.7608 | D13: =C13/(K13/100) -> 537363.53 | E13: =0.9*F13 -> 329555.7 | F13: 366173 | G13: =F13-D13 -> -171190.53 | H13: =0.9*I13 -> 448910.1 | I13: 498789 | J13: =I13-D13 -> -38574.53 | K13: 0.60327146 | L13: ='# and Assessed Value of Parcels'!G8/'# and Assessed Value of Parcels'!O8 -> 0.9566732 | M13: ='# and Assessed Value of Parcels'!H8/'# and Assessed Value of Parcels'!P8 -> 0.84635298 | N13: =(L13+M13)/2 -> 0.90151309 | O13: ='Tax Levies and EQ Tax Rates'!I8 -> 15812581 | P13: =N13*O13 -> 14255249 | Q13: 12748 | R13: =P13/Q13 -> 1118.2342
A14: Bergen | B14: Westwood Borough | C14: =$B$5*R14 -> 3375.8856 | D14: =C14/(K14/100) -> 460151.74 | E14: =0.9*F14 -> 421789.5 | F14: 468655 | G14: =F14-D14 -> 8503.2648 | H14: =0.9*I14 -> 413520.3 | I14: 459467 | J14: =I14-D14 -> -684.73516 | K14: 0.73364618 | L14: ='# and Assessed Value of Parcels'!G9/'# and Assessed Value of Parcels'!O9 -> 0.91940211 | M14: ='# and Assessed Value of Parcels'!H9/'# and Assessed Value of Parcels'!P9 -> 0.75552222 | N14: =(L14+M14)/2 -> 0.83746217 | O14: ='Tax Levies and EQ Tax Rates'!I9 -> 15687741 | P14: =N14*O14 -> 13137890 | Q14: 11282 | R14: =P14/Q14 -> 1164.5
A15: Burlington | B15: Lumberton Township | C15: =$B$5*R15 -> 1133.0912 | D15: =C15/(K15/100) -> 290414.32 | E15: =0.9*F15 -> 419752.95 | F15: 466392.16 | G15: =F15-D15 -> 175977.84 | H15: =0.9*I15 -> 276152.4 | I15: 306836 | J15: =I15-D15 -> 16421.677 | K15: 0.39016368 | L15: ='# and Assessed Value of Parcels'!G10/'# and Assessed Value of Parcels'!O10 -> 0.96040113 | M15: ='# and Assessed Value of Parcels'!H10/'# and Assessed Value of Parcels'!P10 -> 0.85301722 | N15: =(L15+M15)/2 -> 0.90670917 | O15: ='Tax Levies and EQ Tax Rates'!I10 -> 5518999.9 | P15: =N15*O15 -> 5004127.9 | Q15: 12803 | R15: =P15/Q15 -> 390.85588
